[2023-03-03T21:32:04.406+0000] {taskinstance.py:1083} INFO - Dependencies all met for <TaskInstance: sandbox.get_data_goes_from_aws manual__2023-03-03T21:32:00.918839+00:00 [queued]>
[2023-03-03T21:32:04.412+0000] {taskinstance.py:1083} INFO - Dependencies all met for <TaskInstance: sandbox.get_data_goes_from_aws manual__2023-03-03T21:32:00.918839+00:00 [queued]>
[2023-03-03T21:32:04.412+0000] {taskinstance.py:1279} INFO - 
--------------------------------------------------------------------------------
[2023-03-03T21:32:04.412+0000] {taskinstance.py:1280} INFO - Starting attempt 1 of 1
[2023-03-03T21:32:04.413+0000] {taskinstance.py:1281} INFO - 
--------------------------------------------------------------------------------
[2023-03-03T21:32:04.418+0000] {taskinstance.py:1300} INFO - Executing <Task(PythonOperator): get_data_goes_from_aws> on 2023-03-03 21:32:00.918839+00:00
[2023-03-03T21:32:04.434+0000] {standard_task_runner.py:55} INFO - Started process 10316 to run task
[2023-03-03T21:32:04.439+0000] {standard_task_runner.py:82} INFO - Running: ['***', 'tasks', 'run', 'sandbox', 'get_data_goes_from_aws', 'manual__2023-03-03T21:32:00.918839+00:00', '--job-id', '22', '--raw', '--subdir', 'DAGS_FOLDER/noaa.py', '--cfg-path', '/tmp/tmphv5njwyt']
[2023-03-03T21:32:04.440+0000] {standard_task_runner.py:83} INFO - Job 22: Subtask get_data_goes_from_aws
[2023-03-03T21:32:04.505+0000] {task_command.py:388} INFO - Running <TaskInstance: sandbox.get_data_goes_from_aws manual__2023-03-03T21:32:00.918839+00:00 [running]> on host a1445a4c94cf
[2023-03-03T21:32:04.948+0000] {taskinstance.py:1507} INFO - Exporting the following env vars:
AIRFLOW_CTX_DAG_OWNER=***
AIRFLOW_CTX_DAG_ID=sandbox
AIRFLOW_CTX_TASK_ID=get_data_goes_from_aws
AIRFLOW_CTX_EXECUTION_DATE=2023-03-03T21:32:00.918839+00:00
AIRFLOW_CTX_TRY_NUMBER=1
AIRFLOW_CTX_DAG_RUN_ID=manual__2023-03-03T21:32:00.918839+00:00
[2023-03-03T21:32:04.994+0000] {logging_mixin.py:137} INFO - ********************** get_all_geos_file_name_by_filter_new****************
[2023-03-03T21:32:06.831+0000] {logging_mixin.py:137} INFO - get_aws_details_by_filename
[2023-03-03T21:32:06.835+0000] {taskinstance.py:1768} ERROR - Task failed with exception
Traceback (most recent call last):
  File "/home/airflow/.local/lib/python3.9/site-packages/sqlalchemy/engine/base.py", line 1705, in _execute_context
    self.dialect.do_execute(
  File "/home/airflow/.local/lib/python3.9/site-packages/sqlalchemy/engine/default.py", line 716, in do_execute
    cursor.execute(statement, parameters)
psycopg2.errors.UndefinedColumn: column "ABI-L1b-RadC" does not exist
LINE 1: ...tadata(station, year, day, hour, filename) VALUES("ABI-L1b-R...
                                                             ^


The above exception was the direct cause of the following exception:

Traceback (most recent call last):
  File "/home/airflow/.local/lib/python3.9/site-packages/airflow/operators/python.py", line 175, in execute
    return_value = self.execute_callable()
  File "/home/airflow/.local/lib/python3.9/site-packages/airflow/operators/python.py", line 192, in execute_callable
    return self.python_callable(*self.op_args, **self.op_kwargs)
  File "/opt/airflow/dags/main.py", line 68, in get_all_geos_file_name_by_filter_new
    metadata.insert_data_into_goes(station=station_id, year=year, day_of_year=day, hour=hour, filename=file_name)
  File "/opt/airflow/dags/postgres_db_script.py", line 48, in insert_data_into_goes
    self.cursor.execute(insert_str)
  File "/home/airflow/.local/lib/python3.9/site-packages/sqlalchemy/engine/base.py", line 1185, in execute
    return self._exec_driver_sql(
  File "/home/airflow/.local/lib/python3.9/site-packages/sqlalchemy/engine/base.py", line 1484, in _exec_driver_sql
    ret = self._execute_context(
  File "/home/airflow/.local/lib/python3.9/site-packages/sqlalchemy/engine/base.py", line 1748, in _execute_context
    self._handle_dbapi_exception(
  File "/home/airflow/.local/lib/python3.9/site-packages/sqlalchemy/engine/base.py", line 1929, in _handle_dbapi_exception
    util.raise_(
  File "/home/airflow/.local/lib/python3.9/site-packages/sqlalchemy/util/compat.py", line 211, in raise_
    raise exception
  File "/home/airflow/.local/lib/python3.9/site-packages/sqlalchemy/engine/base.py", line 1705, in _execute_context
    self.dialect.do_execute(
  File "/home/airflow/.local/lib/python3.9/site-packages/sqlalchemy/engine/default.py", line 716, in do_execute
    cursor.execute(statement, parameters)
sqlalchemy.exc.ProgrammingError: (psycopg2.errors.UndefinedColumn) column "ABI-L1b-RadC" does not exist
LINE 1: ...tadata(station, year, day, hour, filename) VALUES("ABI-L1b-R...
                                                             ^

[SQL: INSERT INTO goes_metadata(station, year, day, hour, filename) VALUES("ABI-L1b-RadC","2023","001","00","OR_ABI-L1b-RadC-M6C01_G18_s20230010001170_e20230010003544_c20230010003582.nc");]
(Background on this error at: http://sqlalche.me/e/14/f405)
[2023-03-03T21:32:06.865+0000] {taskinstance.py:1318} INFO - Marking task as FAILED. dag_id=sandbox, task_id=get_data_goes_from_aws, execution_date=20230303T213200, start_date=20230303T213204, end_date=20230303T213206
[2023-03-03T21:32:06.896+0000] {standard_task_runner.py:100} ERROR - Failed to execute job 22 for task get_data_goes_from_aws ((psycopg2.errors.UndefinedColumn) column "ABI-L1b-RadC" does not exist
LINE 1: ...tadata(station, year, day, hour, filename) VALUES("ABI-L1b-R...
                                                             ^

[SQL: INSERT INTO goes_metadata(station, year, day, hour, filename) VALUES("ABI-L1b-RadC","2023","001","00","OR_ABI-L1b-RadC-M6C01_G18_s20230010001170_e20230010003544_c20230010003582.nc");]
(Background on this error at: http://sqlalche.me/e/14/f405); 10316)
[2023-03-03T21:32:07.039+0000] {local_task_job.py:208} INFO - Task exited with return code 1
[2023-03-03T21:32:07.090+0000] {taskinstance.py:2578} INFO - 0 downstream tasks scheduled from follow-on schedule check
