[2023-03-03T20:51:39.720+0000] {taskinstance.py:1083} INFO - Dependencies all met for <TaskInstance: sandbox.get_data_goes_from_aws manual__2023-03-03T20:51:35.805458+00:00 [queued]>
[2023-03-03T20:51:39.732+0000] {taskinstance.py:1083} INFO - Dependencies all met for <TaskInstance: sandbox.get_data_goes_from_aws manual__2023-03-03T20:51:35.805458+00:00 [queued]>
[2023-03-03T20:51:39.733+0000] {taskinstance.py:1279} INFO - 
--------------------------------------------------------------------------------
[2023-03-03T20:51:39.734+0000] {taskinstance.py:1280} INFO - Starting attempt 1 of 1
[2023-03-03T20:51:39.734+0000] {taskinstance.py:1281} INFO - 
--------------------------------------------------------------------------------
[2023-03-03T20:51:39.750+0000] {taskinstance.py:1300} INFO - Executing <Task(PythonOperator): get_data_goes_from_aws> on 2023-03-03 20:51:35.805458+00:00
[2023-03-03T20:51:39.769+0000] {standard_task_runner.py:55} INFO - Started process 8208 to run task
[2023-03-03T20:51:39.776+0000] {standard_task_runner.py:82} INFO - Running: ['***', 'tasks', 'run', 'sandbox', 'get_data_goes_from_aws', 'manual__2023-03-03T20:51:35.805458+00:00', '--job-id', '13', '--raw', '--subdir', 'DAGS_FOLDER/noaa.py', '--cfg-path', '/tmp/tmpxbj9r_4m']
[2023-03-03T20:51:39.777+0000] {standard_task_runner.py:83} INFO - Job 13: Subtask get_data_goes_from_aws
[2023-03-03T20:51:39.871+0000] {task_command.py:388} INFO - Running <TaskInstance: sandbox.get_data_goes_from_aws manual__2023-03-03T20:51:35.805458+00:00 [running]> on host a1445a4c94cf
[2023-03-03T20:51:40.388+0000] {taskinstance.py:1507} INFO - Exporting the following env vars:
AIRFLOW_CTX_DAG_OWNER=***
AIRFLOW_CTX_DAG_ID=sandbox
AIRFLOW_CTX_TASK_ID=get_data_goes_from_aws
AIRFLOW_CTX_EXECUTION_DATE=2023-03-03T20:51:35.805458+00:00
AIRFLOW_CTX_TRY_NUMBER=1
AIRFLOW_CTX_DAG_RUN_ID=manual__2023-03-03T20:51:35.805458+00:00
[2023-03-03T20:51:40.415+0000] {logging_mixin.py:137} INFO - ********************** get_all_geos_file_name_by_filter_new****************
[2023-03-03T20:51:42.357+0000] {logging_mixin.py:137} INFO - get_aws_details_by_filename
[2023-03-03T20:51:42.360+0000] {taskinstance.py:1768} ERROR - Task failed with exception
Traceback (most recent call last):
  File "/home/airflow/.local/lib/python3.9/site-packages/airflow/operators/python.py", line 175, in execute
    return_value = self.execute_callable()
  File "/home/airflow/.local/lib/python3.9/site-packages/airflow/operators/python.py", line 192, in execute_callable
    return self.python_callable(*self.op_args, **self.op_kwargs)
  File "/opt/airflow/dags/main.py", line 68, in get_all_geos_file_name_by_filter_new
    Metadata.insert_data_into_goes(station=station, year=year, day_of_year=day, hour=hour, filename=file_name)
TypeError: insert_data_into_goes() missing 1 required positional argument: 'self'
[2023-03-03T20:51:42.379+0000] {taskinstance.py:1318} INFO - Marking task as FAILED. dag_id=sandbox, task_id=get_data_goes_from_aws, execution_date=20230303T205135, start_date=20230303T205139, end_date=20230303T205142
[2023-03-03T20:51:42.397+0000] {standard_task_runner.py:100} ERROR - Failed to execute job 13 for task get_data_goes_from_aws (insert_data_into_goes() missing 1 required positional argument: 'self'; 8208)
[2023-03-03T20:51:42.521+0000] {local_task_job.py:208} INFO - Task exited with return code 1
[2023-03-03T20:51:42.547+0000] {taskinstance.py:2578} INFO - 0 downstream tasks scheduled from follow-on schedule check
